[
  {
    "cmd": [],
    "name": "RECIPE CRASH (Uncaught exception)",
    "~followup_annotations": [
      "@@@STEP_EXCEPTION@@@",
      "The recipe has crashed at point 'Uncaught exception'!",
      "",
      "Traceback (most recent call last):",
      "  File \"RECIPE_REPO[recipe_engine]/recipe_engine/internal/engine.py\", line 601, in run_steps",
      "    raw_result = recipe_obj.run_steps(api, engine)",
      "                 ^^^^^^^^^^^^^^^^^^^^^^^^^^^^^^^^^",
      "  File \"RECIPE_REPO[recipe_engine]/recipe_engine/internal/recipe_deps.py\", line 1009, in run_steps",
      "    recipe_result = invoke_with_properties(",
      "                    ^^^^^^^^^^^^^^^^^^^^^^^",
      "  File \"RECIPE_REPO[recipe_engine]/recipe_engine/internal/property_invoker.py\", line 88, in invoke_with_properties",
      "    return _invoke_with_properties(callable_obj, all_props, environ, prop_defs,",
      "           ^^^^^^^^^^^^^^^^^^^^^^^^^^^^^^^^^^^^^^^^^^^^^^^^^^^^^^^^^^^^^^^^^^^^",
      "  File \"RECIPE_REPO[recipe_engine]/recipe_engine/internal/property_invoker.py\", line 52, in _invoke_with_properties",
      "    return callable_obj(*props, **additional_args)",
      "           ^^^^^^^^^^^^^^^^^^^^^^^^^^^^^^^^^^^^^^^",
      "  File \"RECIPE_REPO[recipe_engine]/recipes/engine_tests/expect_exception.py\", line 17, in RunSteps",
      "    my_function()",
      "  File \"RECIPE_REPO[recipe_engine]/recipes/engine_tests/expect_exception.py\", line 13, in my_function",
      "    raise TypeError(\"BAD DOGE\")",
      "TypeError: BAD DOGE"
    ]
  },
  {
    "failure": {
      "humanReason": "Uncaught Exception: TypeError('BAD DOGE')"
    },
    "name": "$result"
  }
]